Workbook

Sheet Rides
A1: Ride_ID | B1: Platform | C1: Category | D1: Date | E1: Start_Time | F1: End_Time | G1: Duration_Min | H1: Origin_PostCode | I1: Dest_PostCode | J1: Distance_Km | K1: Client_Fare_EUR | L1: Driver_Earnings_EUR | M1: Platform_Fee_EUR | N1: Fee_Pct | O1: EUR_per_Km | P1: EUR_per_Min | Q1: Portagem | R1: Dinamica | S1: Tip
A2: R013 | B2: Uber | C2: Uber X | D2: 46085 | E2: 0.81180556 | F2: 0.82916667 | G2: =(F2-E2)*1440 -> 25 | H2: 2785-115 | I2: 2675-663 | J2: 24.44 | K2: 14.69 | L2: 9.66 | M2: =K2-L2 -> 5.03 | N2: =IFERROR(M2/K2,0) -> 0.3424098 | O2: =IFERROR(L2/J2,0) -> 0.39525368 | P2: =IFERROR(L2/G2,0) -> 0.3864 | Q2: 0.7
A3: R003 | B3: Bolt | C3: Economy | D3: 46085 | E3: 0.83888889 | F3: 0.84930556 | G3: =(F3-E3)*1440 -> 15 | H3: 2675-472 | I3: 1600-196 | J3: 10.2 | K3: 5.9 | L3: 4.42 | M3: =K3-L3 -> 1.48 | N3: =IFERROR(M3/K3,0) -> 0.25084746 | O3: =IFERROR(L3/J3,0) -> 0.43333333 | P3: =IFERROR(L3/G3,0) -> 0.29466667
A4: R009 | B4: Uber | C4: Uber X | D4: 46085 | E4: 0.70069444 | F4: 0.71666667 | G4: =(F4-E4)*1440 -> 23 | H4: 2635-304 | I4: 2610-244 | J4: 14.49 | K4: 9.93 | L4: 6.87 | M4: =K4-L4 -> 3.06 | N4: =IFERROR(M4/K4,0) -> 0.3081571 | O4: =IFERROR(L4/J4,0) -> 0.47412008 | P4: =IFERROR(L4/G4,0) -> 0.29869565
A5: R005 | B5: Uber | C5: Uber X | D5: 46085 | E5: 0.5875 | F5: 0.60416667 | G5: =(F5-E5)*1440 -> 24 | H5: 2690-182 | I5: 1250-096 | J5: 16.6 | K5: 10.96 | L5: 7.99 | M5: =K5-L5 -> 2.97 | N5: =IFERROR(M5/K5,0) -> 0.2709854 | O5: =IFERROR(L5/J5,0) -> 0.4813253 | P5: =IFERROR(L5/G5,0) -> 0.33291667
A6: R002 | B6: Bolt | C6: Economy | D6: 46085 | E6: 0.79930556 | F6: 0.81666667 | G6: =(F6-E6)*1440 -> 25 | H6: 1500-663 | I6: 2785-816 | J6: 17.2 | K6: 11.66 | L6: 8.92 | M6: =K6-L6 -> 2.74 | N6: =IFERROR(M6/K6,0) -> 0.23499142 | O6: =IFERROR(L6/J6,0) -> 0.51860465 | P6: =IFERROR(L6/G6,0) -> 0.3568
A7: R010 | B7: Uber | C7: Uber X Priority | D7: 46085 | E7: 0.72638889 | F7: 0.73541667 | G7: =(F7-E7)*1440 -> 13 | H7: 2720-145 | I7: 2790-226 | J7: 8.07 | K7: 5.97 | L7: 4.21 | M7: =K7-L7 -> 1.76 | N7: =IFERROR(M7/K7,0) -> 0.29480737 | O7: =IFERROR(L7/J7,0) -> 0.52168525 | P7: =IFERROR(L7/G7,0) -> 0.32384615
A8: R006 | B8: Uber | C8: Uber X | D8: 46085 | E8: 0.60833333 | F8: 0.61805556 | G8: =(F8-E8)*1440 -> 14 | H8: 1070-100 | I8: 1300-294 | J8: 7.16 | K8: 5.94 | L8: 3.86 | M8: =K8-L8 -> 2.08 | N8: =IFERROR(M8/K8,0) -> 0.35016835 | O8: =IFERROR(L8/J8,0) -> 0.53910615 | P8: =IFERROR(L8/G8,0) -> 0.27571429
A9: R007 | B9: Uber | C9: Uber X | D9: 46085 | E9: 0.62361111 | F9: 0.63263889 | G9: =(F9-E9)*1440 -> 13 | H9: 1300-291 | I9: 1600-159 | J9: 8.61 | K9: 7.69 | L9: 5.08 | M9: =K9-L9 -> 2.61 | N9: =IFERROR(M9/K9,0) -> 0.33940182 | O9: =IFERROR(L9/J9,0) -> 0.59001161 | P9: =IFERROR(L9/G9,0) -> 0.39076923
A10: R012 | B10: Uber | C10: Uber X | D10: 46085 | E10: 0.78055556 | F10: 0.78958333 | G10: =(F10-E10)*1440 -> 13 | H10: 2760-127 | I10: 1500-288 | J10: 10.56 | K10: 8.96 | L10: 6.53 | M10: =K10-L10 -> 2.43 | N10: =IFERROR(M10/K10,0) -> 0.27120536 | O10: =IFERROR(L10/J10,0) -> 0.61837121 | P10: =IFERROR(L10/G10,0) -> 0.50230769
A11: R008 | B11: Uber | C11: Uber X | D11: 46085 | E11: 0.66805556 | F11: 0.68541667 | G11: =(F11-E11)*1440 -> 25 | H11: 1600-776 | I11: 2635-535 | J11: 19.36 | K11: 16.54 | L11: 13.22 | M11: =K11-L11 -> 3.32 | N11: =IFERROR(M11/K11,0) -> 0.20072551 | O11: =IFERROR(L11/J11,0) -> 0.68285124 | P11: =IFERROR(L11/G11,0) -> 0.5288 | Q11: 1.6
A12: R004 | B12: Bolt | C12: Economy | D12: 46085 | E12: 0.86875 | F12: 0.87847222 | G12: =(F12-E12)*1440 -> 14 | H12: 1700-008 | I12: 1150-200 | J12: 5.6 | K12: 7.18 | L12: 5.38 | M12: =K12-L12 -> 1.8 | N12: =IFERROR(M12/K12,0) -> 0.25069638 | O12: =IFERROR(L12/J12,0) -> 0.96071429 | P12: =IFERROR(L12/G12,0) -> 0.38428571
A13: R001 | B13: Bolt | C13: Bolt | D13: 46085 | E13: 0.77291667 | F13: 0.77708333 | G13: =(F13-E13)*1440 -> 6 | H13: 2790-022 | I13: 2790-379 | J13: 2.2 | K13: 6.12 | L13: 4.59 | M13: =K13-L13 -> 1.53 | N13: =IFERROR(M13/K13,0) -> 0.25 | O13: =IFERROR(L13/J13,0) -> 2.0863636 | P13: =IFERROR(L13/G13,0) -> 0.765
A14: R011 | B14: Uber | C14: Uber X Priority | D14: 46085 | E14: 0.75833333 | F14: 0.76111111 | G14: =(F14-E14)*1440 -> 4 | H14: 2790-114 | I14: 2790-196 | J14: 2.11 | K14: 6.98 | L14: 4.54 | M14: =K14-L14 -> 2.44 | N14: =IFERROR(M14/K14,0) -> 0.3495702 | O14: =IFERROR(L14/J14,0) -> 2.1516588 | P14: =IFERROR(L14/G14,0) -> 1.135
A15: R029 | B15: Uber | C15: Uber X | D15: 46086 | E15: 0.8875 | F15: 0.89791667 | G15: =(F15-E15)*1440 -> 15 | H15: 1200-479 | I15: 1700-087 | J15: 9.27 | K15: 5.96 | L15: 4.36 | M15: =K15-L15 -> 1.6 | N15: =IFERROR(M15/K15,0) -> 0.26845638 | O15: =IFERROR(L15/J15,0) -> 0.47033441 | P15: =IFERROR(L15/G15,0) -> 0.29066667
A16: R018 | B16: Bolt | C16: Economy | D16: 46086 | E16: 0.73333333 | F16: 0.74652778 | G16: =(F16-E16)*1440 -> 19 | H16: 2620-529 | I16: 1495-061 | J16: 16.3 | K16: 10.36 | L16: 7.77 | M16: =K16-L16 -> 2.59 | N16: =IFERROR(M16/K16,0) -> 0.25 | O16: =IFERROR(L16/J16,0) -> 0.47668712 | P16: =IFERROR(L16/G16,0) -> 0.40894737
A17: R017 | B17: Bolt | C17: Economy | D17: 46086 | E17: 0.68819444 | F17: 0.71597222 | G17: =(F17-E17)*1440 -> 40 | H17: 1300-474 | I17: 2620-535 | J17: 18.1 | K17: 10.07 | L17: 9.44 | M17: =K17-L17 -> 0.63 | N17: =IFERROR(M17/K17,0) -> 0.062562066 | O17: =IFERROR(L17/J17,0) -> 0.52154696 | P17: =IFERROR(L17/G17,0) -> 0.236
A18: R026 | B18: Uber | C18: Uber X | D18: 46086 | E18: 0.59513889 | F18: 0.60833333 | G18: =(F18-E18)*1440 -> 19 | H18: 2685-246 | I18: 1000-042 | J18: 8.58 | K18: 6.96 | L18: 4.76 | M18: =K18-L18 -> 2.2 | N18: =IFERROR(M18/K18,0) -> 0.31609195 | O18: =IFERROR(L18/J18,0) -> 0.55477855 | P18: =IFERROR(L18/G18,0) -> 0.25052632
A19: R024 | B19: Bolt | C19: Economy | D19: 46086 | E19: 0.86875 | F19: 0.87847222 | G19: =(F19-E19)*1440 -> 14 | H19: 1400-033 | I19: 1200-109 | J19: 6.5 | K19: 4.5 | L19: 4.13 | M19: =K19-L19 -> 0.37 | N19: =IFERROR(M19/K19,0) -> 0.082222222 | O19: =IFERROR(L19/J19,0) -> 0.63538462 | P19: =IFERROR(L19/G19,0) -> 0.295
A20: R028 | B20: Uber | C20: Uber X Priority | D20: 46086 | E20: 0.84027778 | F20: 0.85486111 | G20: =(F20-E20)*1440 -> 21 | H20: 1600-548 | I20: 1300-107 | J20: 9.93 | K20: 8.99 | L20: 6.9 | M20: =K20-L20 -> 2.09 | N20: =IFERROR(M20/K20,0) -> 0.23248053 | O20: =IFERROR(L20/J20,0) -> 0.69486405 | P20: =IFERROR(L20/G20,0) -> 0.32857143
A21: R025 | B21: Bolt | C21: Economy | D21: 46086 | E21: 0.90555556 | F21: 0.9125 | G21: =(F21-E21)*1440 -> 10 | H21: 1700-096 | I21: 1800-081 | J21: 3.9 | K21: 3.63 | L21: 3.02 | M21: =K21-L21 -> 0.61 | N21: =IFERROR(M21/K21,0) -> 0.16804408 | O21: =IFERROR(L21/J21,0) -> 0.77435897 | P21: =IFERROR(L21/G21,0) -> 0.302
A22: R023 | B22: Bolt | C22: Economy | D22: 46086 | E22: 0.80416667 | F22: 0.81666667 | G22: =(F22-E22)*1440 -> 18 | H22: 1500-179 | I22: 1350-025 | J22: 7.7 | K22: 7.3 | L22: 6.02 | M22: =K22-L22 -> 1.28 | N22: =IFERROR(M22/K22,0) -> 0.17534247 | O22: =IFERROR(L22/J22,0) -> 0.78181818 | P22: =IFERROR(L22/G22,0) -> 0.33444444
A23: R015 | B23: Bolt | C23: Economy | D23: 46086 | E23: 0.62986111 | F23: 0.64791667 | G23: =(F23-E23)*1440 -> 26 | H23: 1100-240 | I23: 1700-008 | J23: 7.7 | K23: 7.66 | L23: 6.31 | M23: =K23-L23 -> 1.35 | N23: =IFERROR(M23/K23,0) -> 0.17624021 | O23: =IFERROR(L23/J23,0) -> 0.81948052 | P23: =IFERROR(L23/G23,0) -> 0.24269231
... A30: R022 | B30: Bolt | C30: Economy | D30: 46086 | E30: 0.79652778 | F30: 0.80138889 | G30: =(F30-E30)*1440 -> 7 | H30: 1500-392 | I30: 1500-353 | J30: 1.3 | K30: 3.77 | L30: 4.04 | M30: =K30-L30 -> -0.27 | N30: =IFERROR(M30/K30,0) -> -0.071618037 | O30: =IFERROR(L30/J30,0) -> 3.1076923 | P30: =IFERROR(L30/G30,0) -> 0.57714286
A31: R038 | B31: Bolt | C31: Economy | D31: 46087 | E31: 0.69722222 | F31: 0.71805556 | G31: =(F31-E31)*1440 -> 30 | H31: 2744-017 | I31: 1750-065 | J31: 22.7 | K31: 10.3 | L31: 9.76 | M31: =K31-L31 -> 0.54 | N31: =IFERROR(M31/K31,0) -> 0.052427184 | O31: =IFERROR(L31/J31,0) -> 0.42995595 | P31: =IFERROR(L31/G31,0) -> 0.32533333 | Q31: 0.4
A32: R031 | B32: Uber | C32: Uber X | D32: 46087 | E32: 0.63611111 | F32: 0.64861111 | G32: =(F32-E32)*1440 -> 18 | H32: 1400-038 | I32: 1500-313 | J32: 11.92 | K32: 7.94 | L32: 5.16 | M32: =K32-L32 -> 2.78 | N32: =IFERROR(M32/K32,0) -> 0.35012594 | O32: =IFERROR(L32/J32,0) -> 0.43288591 | P32: =IFERROR(L32/G32,0) -> 0.28666667
A33: R046 | B33: Bolt | C33: Economy | D33: 46087 | E33: 0.91944444 | F33: 0.92986111 | G33: =(F33-E33)*1440 -> 15 | H33: 1990-083 | I33: 2615-043 | J33: 17.1 | K33: 8.55 | L33: 8.02 | M33: =K33-L33 -> 0.53 | N33: =IFERROR(M33/K33,0) -> 0.061988304 | O33: =IFERROR(L33/J33,0) -> 0.46900585 | P33: =IFERROR(L33/G33,0) -> 0.53466667
A34: R037 | B34: Bolt | C34: Economy | D34: 46087 | E34: 0.67708333 | F34: 0.69375 | G34: =(F34-E34)*1440 -> 24 | H34: 2790-218 | I34: 2785-171 | J34: 11.8 | K34: 7.3 | L34: 6.18 | M34: =K34-L34 -> 1.12 | N34: =IFERROR(M34/K34,0) -> 0.15342466 | O34: =IFERROR(L34/J34,0) -> 0.52372881 | P34: =IFERROR(L34/G34,0) -> 0.2575
A35: R042 | B35: Bolt | C35: Economy | D35: 46087 | E35: 0.80208333 | F35: 0.82291667 | G35: =(F35-E35)*1440 -> 30 | H35: 2735-472 | I35: 1070-051 | J35: 17.5 | K35: 9.94 | L35: 9.31 | M35: =K35-L35 -> 0.63 | N35: =IFERROR(M35/K35,0) -> 0.063380282 | O35: =IFERROR(L35/J35,0) -> 0.532 | P35: =IFERROR(L35/G35,0) -> 0.31033333
A36: R033 | B36: Uber | C36: Uber X | D36: 46087 | E36: 0.83888889 | F36: 0.85694444 | G36: =(F36-E36)*1440 -> 26 | H36: 1300-510 | I36: 1885-010 | J36: 14.98 | K36: 10.96 | L36: 8.11 | M36: =K36-L36 -> 2.85 | N36: =IFERROR(M36/K36,0) -> 0.2600365 | O36: =IFERROR(L36/J36,0) -> 0.54138852 | P36: =IFERROR(L36/G36,0) -> 0.31192308
A37: R043 | B37: Bolt | C37: Economy | D37: 46087 | E37: 0.86458333 | F37: 0.87847222 | G37: =(F37-E37)*1440 -> 20 | H37: 1990-307 | I37: 1070-234 | J37: 11.6 | K37: 6.74 | L37: 6.95 | M37: =K37-L37 -> -0.21 | N37: =IFERROR(M37/K37,0) -> -0.03115727 | O37: =IFERROR(L37/J37,0) -> 0.59913793 | P37: =IFERROR(L37/G37,0) -> 0.3475
A38: R036 | B38: Bolt | C38: Economy | D38: 46087 | E38: 0.65486111 | F38: 0.6625 | G38: =(F38-E38)*1440 -> 11 | H38: 1500-392 | I38: 2790-045 | J38: 6.2 | K38: 5.07 | L38: 3.8 | M38: =K38-L38 -> 1.27 | N38: =IFERROR(M38/K38,0) -> 0.2504931 | O38: =IFERROR(L38/J38,0) -> 0.61290323 | P38: =IFERROR(L38/G38,0) -> 0.34545455
A39: R041 | B39: Bolt | C39: Economy | D39: 46087 | E39: 0.78125 | F39: 0.79652778 | G39: =(F39-E39)*1440 -> 22 | H39: 2795-102 | I39: 2635-353 | J39: 16.2 | K39: 10.81 | L39: 10.22 | M39: =K39-L39 -> 0.59 | N39: =IFERROR(M39/K39,0) -> 0.054579093 | O39: =IFERROR(L39/J39,0) -> 0.6308642 | P39: =IFERROR(L39/G39,0) -> 0.46454545 | Q39: 0.35 | R39: 2.28
A40: R040 | B40: Bolt | C40: Economy | D40: 46087 | E40: 0.76180556 | F40: 0.77777778 | G40: =(F40-E40)*1440 -> 23 | H40: 1200-869 | I40: 2795-208 | J40: 10.3 | K40: 6.6 | L40: 7.07 | M40: =K40-L40 -> -0.47 | N40: =IFERROR(M40/K40,0) -> -0.071212121 | O40: =IFERROR(L40/J40,0) -> 0.68640777 | P40: =IFERROR(L40/G40,0) -> 0.3073913
A41: R034 | B41: Bolt | C41: Economy | D41: 46087 | E41: 0.55902778 | F41: 0.56875 | G41: =(F41-E41)*1440 -> 14 | H41: 2615-037 | I41: 2625-082 | J41: 6.2 | K41: 5.12 | L41: 4.27 | M41: =K41-L41 -> 0.85 | N41: =IFERROR(M41/K41,0) -> 0.16601563 | O41: =IFERROR(L41/J41,0) -> 0.68870968 | P41: =IFERROR(L41/G41,0) -> 0.305
A42: R035 | B42: Bolt | C42: Economy | D42: 46087 | E42: 0.62222222 | F42: 0.6375 | G42: =(F42-E42)*1440 -> 22 | H42: 1100-148 | I42: 1400-034 | J42: 7.3 | K42: 6.9 | L42: 5.17 | M42: =K42-L42 -> 1.73 | N42: =IFERROR(M42/K42,0) -> 0.25072464 | O42: =IFERROR(L42/J42,0) -> 0.70821918 | P42: =IFERROR(L42/G42,0) -> 0.235
A43: R044 | B43: Bolt | C43: Economy | D43: 46087 | E43: 0.87986111 | F43: 0.88680556 | G43: =(F43-E43)*1440 -> 10 | H43: 1070-066 | I43: 1700-008 | J43: 6.7 | K43: 6.8 | L43: 5.1 | M43: =K43-L43 -> 1.7 | N43: =IFERROR(M43/K43,0) -> 0.25 | O43: =IFERROR(L43/J43,0) -> 0.76119403 | P43: =IFERROR(L43/G43,0) -> 0.51 | R43: 1.14
A44: R030 | B44: Uber | C44: Share | D44: 46087 | E44: 0.56805556 | F44: 0.60486111 | G44: =(F44-E44)*1440 -> 53 | H44: 2625-005 | I44: 1100-316 | J44: 18.92 | K44: 17.35 | L44: 15.08 | M44: =K44-L44 -> 2.27 | N44: =IFERROR(M44/K44,0) -> 0.13083573 | O44: =IFERROR(L44/J44,0) -> 0.79704017 | P44: =IFERROR(L44/G44,0) -> 0.2845283
A45: R032 | B45: Uber | C45: Uber X Priority | D45: 46087 | E45: 0.82361111 | F45: 0.83263889 | G45: =(F45-E45)*1440 -> 13 | H45: 1050-020 | I45: 1300-319 | J45: 7.53 | K45: 9.97 | L45: 6.48 | M45: =K45-L45 -> 3.49 | N45: =IFERROR(M45/K45,0) -> 0.35005015 | O45: =IFERROR(L45/J45,0) -> 0.86055777 | P45: =IFERROR(L45/G45,0) -> 0.49846154
A46: R045 | B46: Bolt | C46: Bolt | D46: 46087 | E46: 0.8875 | F46: 0.89722222 | G46: =(F46-E46)*1440 -> 14 | H46: 1700-008 | I46: 1150-195 | J46: 5.4 | K46: 5.71 | L46: 4.75 | M46: =K46-L46 -> 0.96 | N46: =IFERROR(M46/K46,0) -> 0.16812609 | O46: =IFERROR(L46/J46,0) -> 0.87962963 | P46: =IFERROR(L46/G46,0) -> 0.33928571
...

Sheet Fuel
A1: Week | B1: Refuel_Date | C1: PRIO_Amount_EUR | D1: Liters | E1: EUR_per_Liter | F1: Week_Km | G1: Fuel_Cost_per_Km | H1: Week_Earnings_EUR | I1: Fuel_Pct_Earnings | J1: Net_Profit_EUR | K1: Notes
A2: W20/2026 | B2: 12/05/2026 | C2: 55 | D2: 42.3 | E2: =IFERROR(C2/D2,0) -> 1.3002364 | F2: =IFERROR(SUMPRODUCT((TEXT(DATEVALUE(Rides!D2:D4999),"YYYY-WW")=TEXT(DATEVALUE(B2),"YYYY-WW"))*Rides!J2:J4999),0) -> 0 | G2: =IFERROR(C2/F2,0) -> 0 | H2: =IFERROR(SUMPRODUCT((TEXT(DATEVALUE(Rides!D2:D4999),"YYYY-WW")=TEXT(DATEVALUE(B2),"YYYY-WW"))*Rides!L2:L4999),0) -> 0 | I2: =IFERROR(C2/H2,0) -> 0 | J2: =IFERROR(H2-C2,0) -> -55
A3: W19/2026 | B3: 05/05/2026 | C3: 48.5 | D3: 37.1 | E3: =IFERROR(C3/D3,0) -> 1.3072776 | F3: =IFERROR(SUMPRODUCT((TEXT(DATEVALUE(Rides!D2:D4999),"YYYY-WW")=TEXT(DATEVALUE(B3),"YYYY-WW"))*Rides!J2:J4999),0) -> 0 | G3: =IFERROR(C3/F3,0) -> 0 | H3: =IFERROR(SUMPRODUCT((TEXT(DATEVALUE(Rides!D2:D4999),"YYYY-WW")=TEXT(DATEVALUE(B3),"YYYY-WW"))*Rides!L2:L4999),0) -> 0 | I3: =IFERROR(C3/H3,0) -> 0 | J3: =IFERROR(H3-C3,0) -> -48.5
A4: TOTAL | C4: =SUM(C2:C3) -> 103.5 | D4: =SUM(D2:D3) -> 79.4 | E4: =IFERROR(C4/D4,0) -> 1.3035264 | F4: =SUM(F2:F3) -> 0 | G4: =IFERROR(C4/F4,0) -> 0 | H4: =SUM(H2:H3) -> 0 | I4: =IFERROR(C4/H4,0) -> 0 | J4: =SUM(J2:J3) -> -103.5

Sheet Monthly_Summary
B1: 📊 MONTHLY SUMMARY — TVDE
B3: RIDES
B4: Total Rides | C4: =COUNTA(Rides!A2:A4999) -> 2600
B5: Total Distance (Km) | C5: =SUM(Rides!J2:J4999) -> 23951.11
B6: Total Duration (Min) | C6: =SUM(Rides!G2:G4999) -> 40785
B7: Total Duration (Hours) | C7: =IFERROR(C6/60,0) -> 679.75
B8: Avg Distance per Ride (Km) | C8: =IFERROR(C5/C4,0) -> 9.2119654
B9: Avg Duration per Ride (Min) | C9: =IFERROR(C6/C4,0) -> 15.686538
B11: EARNINGS
B12: Total Client Fare (€) | C12: =SUM(Rides!K2:K4999) -> 20630.36
B13: Total Driver Earnings (€) | C13: =SUM(Rides!L2:L4999) -> 15986.7
B14: Total Platform Fees (€) | C14: =SUM(Rides!M2:M4999) -> 4643.66
B15: Avg Platform Fee % | C15: =IFERROR(C14/C12,0) -> 0.22508866
B16: Earnings per Km (€) | C16: =IFERROR(C13/C5,0) -> 0.6674722
B17: Earnings per Hour (€) | C17: =IFERROR(C13/C7,0) -> 23.518499
B18: Earnings per Ride (€) | C18: =IFERROR(C13/C4,0) -> 6.1487308
B20: BY PLATFORM
B21: Uber — Total Rides | C21: =COUNTIF(Rides!B2:B4999,"Uber") -> 1099
B22: Uber — Driver Earnings (€) | C22: =SUMIF(Rides!B2:B4999,"Uber",Rides!L2:L4999) -> 6903.59
B23: Bolt — Total Rides | C23: =COUNTIF(Rides!B2:B4999,"Bolt") -> 1272
B24: Bolt — Driver Earnings (€) | C24: =SUMIF(Rides!B2:B4999,"Bolt",Rides!L2:L4999) -> 7918.26
B26: FUEL
B27: Total Fuel Cost — PRIO (€) | C27: =SUM(Fuel!C2:C5000) -> 207
B28: Avg Fuel Cost per Km (€) | C28: =IFERROR(C27/C5,0) -> 0.0086426057
B29: Fuel % of Driver Earnings | C29: =IFERROR(C27/C13,0) -> 0.012948263
B30: Net Profit after Fuel (€) | C30: =IFERROR(C13-C27,0) -> 15779.7
B31: Net Profit per Hour (€) | C31: =IFERROR(C30/C7,0) -> 23.213976

Sheet Data_Dictionary
B1: DATA DICTIONARY — TVDE Rides Database
B3: Field | C3: Description | D3: Example | E3: Entry Type
B4: — RIDES TABLE —
B5: Ride_ID | C5: Unique sequential ride identifier | D5: R001 | E5: Manual
B6: Platform | C6: Ride-hailing app used | D6: Uber / Bolt | E6: Manual
B7: Category | C7: Service tier offered by the platform | D7: UberX / Economy | E7: Manual
B8: Date | C8: Date the ride took place (DD/MM/YYYY) | D8: 13/05/2026 | E8: Manual
B9: Day_of_Week | C9: Day of the week | D9: Wednesday | E9: Manual
B10: Start_Time | C10: Ride start time (HH:MM) | D10: 19:21 | E10: Manual
B11: End_Time | C11: Ride end time (HH:MM) | D11: 19:38 | E11: Manual
B12: Duration_Min | C12: Ride duration in minutes (decimal) | D12: 17.58 | E12: Manual
B13: Origin_PostCode | C13: Postal code where the ride started | D13: 2685-343 | E13: Manual
B14: Dest_PostCode | C14: Postal code where the ride ended | D14: 2625-583 | E14: Manual
B15: Distance_Km | C15: Total distance of the ride in kilometres | D15: 18.31 | E15: Manual
B16: Client_Fare_EUR | C16: Total amount paid by the passenger | D16: 11.96 € | E16: Manual
... B21: EUR_per_Min | C21: Driver earnings divided by duration | D21: 0.46 €/min | E21: Formula
B22: — FUEL TABLE —
B23: Week | C23: Week reference label | D23: W20/2026 | E23: Manual
B24: Refuel_Date | C24: Date of PRIO refuel | D24: 12/05/2026 | E24: Manual
B25: PRIO_Amount_EUR | C25: Total amount paid at PRIO that week | D25: 55.00 € | E25: Manual
B26: Liters | C26: Litres fuelled that week | D26: 42.30 L | E26: Manual
B27: EUR_per_Liter | C27: Price per litre (auto-calculated) | D27: 1.30 €/L | E27: Formula
B28: Week_Km | C28: Total km driven that week (from Rides tab) | D28: 210.5 km | E28: Formula (cross-sheet)
B29: Fuel_Cost_per_Km | C29: Fuel cost divided by km driven | D29: 0.26 €/km | E29: Formula
B30: Week_Earnings_EUR | C30: Total driver earnings that week (from Rides tab) | D30: 92.40 € | E30: Formula (cross-sheet)
B31: Fuel_Pct_Earnings | C31: Fuel cost as % of driver earnings | D31: 59.5% | E31: Formula
B32: Net_Profit_EUR | C32: Driver earnings minus fuel cost | D32: 37.40 € | E32: Formula
